Workbook

Sheet Instructions
A1: MS Excel Practical Exam
A2: Total Questions: 30
A3: Difficulty Level: Medium
A4: Syllabus: Formulas, Logical Functions, Lookups, INDEX-MATCH, Pivot Tables & Charts, Data Analysis
A5: Attempt all questions using appropriate Excel tools/functions.

Sheet Sales_Data
A1: Order_ID | B1: Region | C1: Salesperson | D1: Product | E1: Quantity | F1: Unit_Price | G1: Sales_Date
A2: 301 | B2: North | C2: Amit | D2: Laptop | E2: 2 | F2: 45000 | G2: 05-01-2025
A3: 302 | B3: South | C3: Riya | D3: Mobile | E3: 5 | F3: 15000 | G3: 07-01-2025
A4: 303 | B4: East | C4: Kunal | D4: Tablet | E4: 3 | F4: 18000 | G4: 10-01-2025
A5: 304 | B5: West | C5: Neha | D5: Laptop | E5: 1 | F5: 45000 | G5: 12-01-2025
A6: 305 | B6: North | C6: Amit | D6: Mobile | E6: 4 | F6: 15000 | G6: 15-01-2025
A7: 306 | B7: South | C7: Riya | D7: Laptop | E7: 2 | F7: 45000 | G7: 18-01-2025

Sheet Sheet2
C4: qun:-1 | E4: calculate sales each of | G4: ordar
C6: Order_ID | D6: Region | E6: Salesperson | F6: Product | G6: Quantity | H6: Unit_Price | I6: Sales_Date | J6: Total sales
C7: 301 | D7: North | E7: Amit | F7: Laptop | G7: 2 | H7: 45000 | I7: 05-01-2025 | J7: =H7*G7 -> 90000
C8: 302 | D8: South | E8: Riya | F8: Mobile | G8: 5 | H8: 15000 | I8: 07-01-2025 | J8: =H8*G8 -> 75000
C9: 303 | D9: East | E9: Kunal | F9: Tablet | G9: 3 | H9: 18000 | I9: 10-01-2025 | J9: =H9*G9 -> 54000
C10: 304 | D10: West | E10: Neha | F10: Laptop | G10: 1 | H10: 45000 | I10: 12-01-2025 | J10: =H10*G10 -> 45000
C11: 305 | D11: North | E11: Amit | F11: Mobile | G11: 4 | H11: 15000 | I11: 15-01-2025 | J11: =H11*G11 -> 60000
C12: 306 | D12: South | E12: Riya | F12: Laptop | G12: 2 | H12: 45000 | I12: 18-01-2025 | J12: =H12*G12 -> 90000

Sheet Sheet5
C3: 4. Find Grand Total of Final Amount.
C5: Column1 | D5: Region | E5: Salesperson | F5: Product | G5: Order_ID2 | H5: Region3 | I5: Salesperson4 | J5: Product5 | K5: Order_ID6 | L5: Region7 | M5: Salesperson2
C6: 301 | D6: North | E6: Amit | F6: Laptop | G6: 301 | H6: North | I6: Amit | J6: Laptop | K6: 301 | L6: North | M6: Amit
C7: 302 | D7: South | E7: Riya | F7: Mobile | G7: 302 | H7: South | I7: Riya | J7: Mobile | K7: 302 | L7: South | M7: Riya
C8: 303 | D8: East | E8: Kunal | F8: Tablet | G8: 303 | H8: East | I8: Kunal | J8: Tablet | K8: 303 | L8: East | M8: Kunal
C9: 304 | D9: West | E9: Neha | F9: Laptop | G9: 304 | H9: West | I9: Neha | J9: Laptop | K9: 304 | L9: West | M9: Neha
C10: 305 | D10: North | E10: Amit | F10: Mobile | G10: 4 | H10: 15000 | I10: 15-01-2025 | J10: =H10*G10 -> 60000 | K10: =J10*18% -> 10800 | L10: =J10+K10 -> 70800
C11: 306 | D11: South | E11: Riya | F11: Laptop | G11: 2 | H11: 45000 | I11: 18-01-2025 | J11: =H11*G11 -> 90000 | K11: =J11*18% -> 16200 | L11: =J11+K11 -> 106200
D16: 5. Count total number of orders using COUNTA.
D18: Order_ID | E18: Region | F18: Salesperson | G18: Product | H18: Quantity | I18: Unit_Price | J18: Sales_Date | K18: Total sales | L18: GST | M18: FINALGST | N18: COUNT
D19: 301 | E19: North | F19: Amit | G19: Laptop | H19: 2 | I19: 45000 | J19: 05-01-2025 | K19: =I19*H19 -> 90000 | L19: =VLOOKUP(G19,Product_Master!$A$1:$C$4,3,FALSE*Sales_Data!G15) -> 18 | M19: =K19+L19 -> 90018 | N19: =COUNT(D18:D24) -> 6
D20: 302 | E20: South | F20: Riya | G20: Mobile | H20: 5 | I20: 15000 | J20: 07-01-2025 | K20: =I20*H20 -> 75000 | L20: =VLOOKUP(G20,Product_Master!$A$1:$C$4,3,FALSE*Sales_Data!G16) -> 12 | M20: =K20+L20 -> 75012
D21: 303 | E21: East | F21: Kunal | G21: Tablet | H21: 3 | I21: 18000 | J21: 10-01-2025 | K21: =I21*H21 -> 54000 | L21: =VLOOKUP(G21,Product_Master!$A$1:$C$4,3,FALSE*Sales_Data!G17) -> 12 | M21: =K21+L21 -> 54012
D22: 304 | E22: West | F22: Neha | G22: Laptop | H22: 1 | I22: 45000 | J22: 12-01-2025 | K22: =I22*H22 -> 45000 | L22: =VLOOKUP(G22,Product_Master!$A$1:$C$4,3,FALSE*Sales_Data!G18) -> 18 | M22: =K22+L22 -> 45018
D23: 305 | E23: North | F23: Amit | G23: Mobile | H23: 4 | I23: 15000 | J23: 15-01-2025 | K23: =I23*H23 -> 60000 | L23: =VLOOKUP(G23,Product_Master!$A$1:$C$4,3,FALSE*Sales_Data!G19) -> 12 | M23: =K23+L23 -> 60012
D24: 306 | E24: South | F24: Riya | G24: Laptop | H24: 2 | I24: 45000 | J24: 18-01-2025 | K24: =I24*H24 -> 90000 | L24: =VLOOKUP(G24,Product_Master!$A$1:$C$4,3,FALSE*Sales_Data!G20) -> 18 | M24: =K24+L24 -> 90018
D28: 7 | E28: 7. Use IF to classify Quantity as High (>3) or Low (<=3).
D29: Order_ID | E29: Region | F29: Salesperson | G29: Product | H29: Quantity | I29: Unit_Price | J29: Sales_Date | K29: Total sales
D30: 301 | E30: North | F30: Amit | G30: Laptop | H30: 2 | I30: 45000 | J30: 05-01-2025 | K30: =I30*H30 -> 90000 | L30: {=IF(H30:H35<3,"high","low")} -> high
D31: 302 | E31: South | F31: Riya | G31: Mobile | H31: 5 | I31: 15000 | J31: 07-01-2025 | K31: =I31*H31 -> 75000 | L31: low
D32: 303 | E32: East | F32: Kunal | G32: Tablet | H32: 3 | I32: 18000 | J32: 10-01-2025 | K32: =I32*H32 -> 54000 | L32: low
D33: 304 | E33: West | F33: Neha | G33: Laptop | H33: 1 | I33: 45000 | J33: 12-01-2025 | K33: =I33*H33 -> 45000 | L33: high
D34: 305 | E34: North | F34: Amit | G34: Mobile | H34: 4 | I34: 15000 | J34: 15-01-2025 | K34: =I34*H34 -> 60000 | L34: low
D35: 306 | E35: South | F35: Riya | G35: Laptop | H35: 2 | I35: 45000 | J35: 18-01-2025 | K35: =I35*H35 -> 90000 | L35: high
D38: 8 | E38: 8. Find the maximum and minimum Final Amount.
D39: Order_ID | E39: Region | F39: Salesperson | G39: Product | H39: Quantity | I39: Unit_Price | J39: Sales_Date | K39: Total sales | L39: min | M39: max
D40: 301 | E40: North | F40: Amit | G40: Laptop | H40: 2 | I40: 45000 | J40: 05-01-2025 | K40: =I40*H40 -> 90000 | L40: =MIN(K40) -> 90000 | M40: =MAX(K40) -> 90000
D41: 302 | E41: South | F41: Riya | G41: Mobile | H41: 5 | I41: 15000 | J41: 07-01-2025 | K41: =I41*H41 -> 75000 | L41: =MIN(K41) -> 75000 | M41: =MAX(K41) -> 75000
D42: 303 | E42: East | F42: Kunal | G42: Tablet | H42: 3 | I42: 18000 | J42: 10-01-2025 | K42: =I42*H42 -> 54000 | L42: =MIN(K42) -> 54000 | M42: =MAX(K42) -> 54000
D43: 304 | E43: West | F43: Neha | G43: Laptop | H43: 1 | I43: 45000 | J43: 12-01-2025 | K43: =I43*H43 -> 45000 | L43: =MIN(K43) -> 45000 | M43: =MAX(K43) -> 45000
D44: 305 | E44: North | F44: Amit | G44: Mobile | H44: 4 | I44: 15000 | J44: 15-01-2025 | K44: =I44*H44 -> 60000 | L44: =MIN(K44) -> 60000 | M44: =MAX(K44) -> 60000
D45: 306 | E45: South | F45: Riya | G45: Laptop | H45: 2 | I45: 45000 | J45: 18-01-2025 | K45: =I45*H45 -> 90000 | L45: =MIN(K45) -> 90000 | M45: =MAX(K45) -> 90000
D48: 9 | E48: 9. Extract month name from Sales_Date.
D49: Order_ID | E49: Region | F49: Salesperson | G49: Product | H49: Quantity | I49: Unit_Price | J49: Sales_Date | K49: Total sales
D50: 301 | E50: North | F50: Amit | G50: Laptop | H50: 2 | I50: 45000 | J50: 05-01-2025 | K50: =I50*H50 -> 90000 | L50: =TEXT(J50,"mmmm") -> January
D51: 302 | E51: South | F51: Riya | G51: Mobile | H51: 5 | I51: 15000 | J51: 07-01-2025 | K51: =I51*H51 -> 75000 | L51: =TEXT(J51,"mmmm") -> January
D52: 303 | E52: East | F52: Kunal | G52: Tablet | H52: 3 | I52: 18000 | J52: 10-01-2025 | K52: =I52*H52 -> 54000 | L52: =TEXT(J52,"mmmm") -> January
D53: 304 | E53: West | F53: Neha | G53: Laptop | H53: 1 | I53: 45000 | J53: 12-01-2025 | K53: =I53*H53 -> 45000 | L53: =TEXT(J53,"mmmm") -> January
D54: 305 | E54: North | F54: Amit | G54: Mobile | H54: 4 | I54: 15000 | J54: 15-01-2025 | K54: =I54*H54 -> 60000 | L54: =TEXT(J54,"mmmm") -> January
D55: 306 | E55: South | F55: Riya | G55: Laptop | H55: 2 | I55: 45000 | J55: 18-01-2025 | K55: =I55*H55 -> 90000 | L55: =TEXT(J55,"mmmm") -> January
...

Sheet Sheet7
B2: 12 | C2: 12. Calculate average marks of each student.
B3: Student_ID | C3: Name | D3: Maths | E3: Statistics | F3: Excel | G3: Attendance_% | I3: avrange
B4: 1 | C4: Rahul | D4: 78 | E4: 82 | F4: 85 | G4: 92 | I4: =AVERAGE(D4:F4) -> 81.666667
B5: 2 | C5: Sneha | D5: 88 | E5: 91 | F5: 90 | G5: 96 | I5: =AVERAGE(D5:F5) -> 89.666667
B6: 3 | C6: Arjun | D6: 65 | E6: 70 | F6: 72 | G6: 85 | I6: =AVERAGE(D6:F6) -> 69
B7: 4 | C7: Pooja | D7: 92 | E7: 89 | F7: 94 | G7: 98 | I7: =AVERAGE(D7:F7) -> 91.666667
B8: 5 | C8: Vikas | D8: 55 | E8: 60 | F8: 58 | G8: 80 | I8: =AVERAGE(D8:F8) -> 57.666667
B11: 13 | C11: 13. Find the topper based on average marks.
B12: Student_ID | C12: Name | D12: Maths | E12: Statistics | F12: Excel | G12: Attendance_% | I12: avrange
B13: 1 | C13: Rahul | D13: 78 | E13: 82 | F13: 85 | G13: 92 | I13: =AVERAGE(D13:F13) -> 81.666667
B14: 2 | C14: Sneha | D14: 88 | E14: 91 | F14: 90 | G14: 96 | I14: =AVERAGE(D14:F14) -> 89.666667
B15: 3 | C15: Arjun | D15: 65 | E15: 70 | F15: 72 | G15: 85 | I15: =AVERAGE(D15:F15) -> 69
B16: 4 | C16: Pooja | D16: 92 | E16: 89 | F16: 94 | G16: 98 | I16: =AVERAGE(D16:F16) -> 91.666667
B17: 5 | C17: Vikas | D17: 55 | E17: 60 | F17: 58 | G17: 80 | I17: =AVERAGE(D17:F17) -> 57.666667
B19: 14 | C19: 14. Count students with Attendance above 90%.
B20: Student_ID | C20: Name | D20: Maths | E20: Statistics | F20: Excel | G20: Attendance_%
B21: 1 | C21: Rahul | D21: 78 | E21: 82 | F21: 85 | G21: 92 | H21: =COUNTIF(G21:G25,">90") -> 3
B22: 2 | C22: Sneha | D22: 88 | E22: 91 | F22: 90 | G22: 96 | H22: =COUNTIF(G22:G26,">90") -> 2
B23: 3 | C23: Arjun | D23: 65 | E23: 70 | F23: 72 | G23: 85 | H23: =COUNTIF(G23:G27,">90") -> 1
B24: 4 | C24: Pooja | D24: 92 | E24: 89 | F24: 94 | G24: 98 | H24: =COUNTIF(G24:G28,">90") -> 1
B25: 5 | C25: Vikas | D25: 55 | E25: 60 | F25: 58 | G25: 80 | H25: =COUNTIF(G25:G29,">90") -> 1
B27: 15. Use IF to classify students as Eligible (Attendance >= 85%).
B28: Student_ID | C28: Name | D28: Maths | E28: Statistics | F28: Excel | G28: Attendance_% | I28: ELIGIBLE
B29: 1 | C29: Rahul | D29: 78 | E29: 82 | F29: 85 | G29: 92 | I29: =IF(G29>=85%,"Eligible","Not Eligible") -> Eligible
B30: 2 | C30: Sneha | D30: 88 | E30: 91 | F30: 90 | G30: 96 | I30: =IF(G30>=85%,"Eligible","Not Eligible") -> Eligible
B31: 3 | C31: Arjun | D31: 65 | E31: 70 | F31: 72 | G31: 85 | I31: =IF(G31>=85%,"Eligible","Not Eligible") -> Eligible
B32: 4 | C32: Pooja | D32: 92 | E32: 89 | F32: 94 | G32: 98 | I32: =IF(G32>=85%,"Eligible","Not Eligible") -> Eligible
B33: 5 | C33: Vikas | D33: 55 | E33: 60 | F33: 58 | G33: 80 | I33: =IF(G33>=85%,"Eligible","Not Eligible") -> Eligible

Sheet Product_Master
A1: Product | B1: Category | C1: GST_%
A2: Laptop | B2: Electronics | C2: 18
A3: Mobile | B3: Electronics | C3: 12
A4: Tablet | B4: Electronics | C4: 12

Sheet Sheet3
D3: qun:-2 calculate vlookup
D6: Product | E6: Category | F6: GST_%
D7: Laptop | E7: Electronics | F7: 18
D8: Mobile | E8: Electronics | F8: 12
D9: Tablet | E9: Electronics | F9: 12
G11: Product | H11: Gst
G12: Laptop | H12: =VLOOKUP(G12,D7:F9,3,0) -> 18

Sheet Student_Marks
A1: Student_ID | B1: Name | C1: Maths | D1: Statistics | E1: Excel | F1: Attendance_%
A2: 1 | B2: Rahul | C2: 78 | D2: 82 | E2: 85 | F2: 92
A3: 2 | B3: Sneha | C3: 88 | D3: 91 | E3: 90 | F3: 96
A4: 3 | B4: Arjun | C4: 65 | D4: 70 | E4: 72 | F4: 85
A5: 4 | B5: Pooja | C5: 92 | D5: 89 | E5: 94 | F5: 98
A6: 5 | B6: Vikas | C6: 55 | D6: 60 | E6: 58 | F6: 80

Sheet Questions
A1: 1. Calculate Total Sales for each order (Quantity × Unit_Price). | J1: 2
A2: 2. Calculate GST Amount using VLOOKUP from Product_Master. | J2: 2
A3: 3. Find Final Amount payable (Total Sales + GST). | J3: 2
A4: 4. Find Grand Total of Final Amount. | J4: 2
A5: 5. Count total number of orders using COUNTA. | J5: 2
A6: 6. Find Region-wise total sales using SUMIF. | J6: 2
A7: 7. Use IF to classify Quantity as High (>3) or Low (<=3). | J7: 2
A8: 8. Find the maximum and minimum Final Amount. | J8: 2
A9: 9. Extract month name from Sales_Date. | J9: 2
A10: 10. Sort Sales_Data by Final Amount (Descending). | J10: 2
A11: 11. Use INDEX-MATCH to fetch Product Category. | J11: 2
A12: 12. Calculate average marks of each student. | J12: 2
... A30: 30. Protect the Student_Marks sheet. | J30: 2
J32: =SUM(J1:J30) -> 60

Sheet Sheet8
A1: 16. Create a Pivot Table showing Product-wise Total Sales.
B3: Order_ID | C3: Region | D3: Salesperson | E3: Product | F3: Quantity | G3: Unit_Price | H3: Sales_Date | I3: Total sales
B4: 301 | C4: North | D4: Amit | E4: Laptop | F4: 2 | G4: 45000 | H4: 05-01-2025 | I4: =G4*F4 -> 90000
B5: 306 | C5: South | D5: Riya | E5: Laptop | F5: 2 | G5: 45000 | H5: 18-01-2025 | I5: =G5*F5 -> 90000
B6: 302 | C6: South | D6: Riya | E6: Mobile | F6: 5 | G6: 15000 | H6: 07-01-2025 | I6: =G6*F6 -> 75000
B7: 305 | C7: North | D7: Amit | E7: Mobile | F7: 4 | G7: 15000 | H7: 15-01-2025 | I7: =G7*F7 -> 60000
B8: 303 | C8: East | D8: Kunal | E8: Tablet | F8: 3 | G8: 18000 | H8: 10-01-2025 | I8: =G8*F8 -> 54000
B9: 304 | C9: West | D9: Neha | E9: Laptop | F9: 1 | G9: 45000 | H9: 12-01-2025 | I9: =G9*F9 -> 45000
E11: Row Labels | F11: Sum of Total sales
E12: Laptop | F12: 225000
E13: Mobile | F13: 135000
E14: Tablet | F14: 54000
E15: Grand Total | F15: 414000
D28: 17. Create a Pivot Table showing Region-wise Total Sales.

Sheet Sheet6
B4: QUN:-6 | C4: 6. Find Region-wise total sales using SUMIF.
C6: Order_ID | D6: Region | E6: Salesperson | F6: Product | G6: Quantity | H6: Unit_Price | I6: Sales_Date
C7: 301 | D7: North | E7: Amit | F7: Laptop | G7: 2 | H7: 45000 | I7: 05-01-2025
C8: 302 | D8: South | E8: Riya | F8: Mobile | G8: 5 | H8: 15000 | I8: 07-01-2025
C9: 303 | D9: East | E9: Kunal | F9: Tablet | G9: 3 | H9: 18000 | I9: 10-01-2025
C10: 304 | D10: West | E10: Neha | F10: Laptop | G10: 1 | H10: 45000 | I10: 12-01-2025
C11: 305 | D11: North | E11: Amit | F11: Mobile | G11: 4 | H11: 15000 | I11: 15-01-2025
C12: 306 | D12: South | E12: Riya | F12: Laptop | G12: 2 | H12: 45000 | I12: 18-01-2025

Sheet Sheet1
B4: QUN:1 | C4: 12. Calculate average marks of each student.
B6: Student_ID | C6: Name | D6: Maths | E6: Statistics | F6: Excel | G6: Attendance_% | I6: AVERAGE
B7: 1 | C7: Rahul | D7: 78 | E7: 82 | F7: 85 | G7: 92 | I7: =AVERAGE(D7:F7) -> 81.666667
B8: 2 | C8: Sneha | D8: 88 | E8: 91 | F8: 90 | G8: 96 | I8: =AVERAGE(D8:F8) -> 89.666667
B9: 3 | C9: Arjun | D9: 65 | E9: 70 | F9: 72 | G9: 85 | I9: =AVERAGE(D9:F9) -> 69
B10: 4 | C10: Pooja | D10: 92 | E10: 89 | F10: 94 | G10: 98 | I10: =AVERAGE(D10:F10) -> 91.666667
B11: 5 | C11: Vikas | D11: 55 | E11: 60 | F11: 58 | G11: 80 | I11: =AVERAGE(D11:F11) -> 57.666667

Sheet Sheet4
D3: QUN:-3 FIND OUT GST
C5: Order_ID | D5: Region | E5: Salesperson | F5: Product | G5: Quantity | H5: Unit_Price | I5: Sales_Date | J5: Total sales | K5: GST | L5: FINALGST
C6: 301 | D6: North | E6: Amit | F6: Laptop | G6: 2 | H6: 45000 | I6: 05-01-2025 | J6: =H6*G6 -> 90000 | K6: =VLOOKUP(F6,Product_Master!$A$1:$C$4,3,FALSE*Sales_Data!F2) -> 18 | L6: =J6+K6 -> 90018
C7: 302 | D7: South | E7: Riya | F7: Mobile | G7: 5 | H7: 15000 | I7: 07-01-2025 | J7: =H7*G7 -> 75000 | K7: =VLOOKUP(F7,Product_Master!$A$1:$C$4,3,FALSE*Sales_Data!F3) -> 12 | L7: =J7+K7 -> 75012
C8: 303 | D8: East | E8: Kunal | F8: Tablet | G8: 3 | H8: 18000 | I8: 10-01-2025 | J8: =H8*G8 -> 54000 | K8: =VLOOKUP(F8,Product_Master!$A$1:$C$4,3,FALSE*Sales_Data!F4) -> 12 | L8: =J8+K8 -> 54012
C9: 304 | D9: West | E9: Neha | F9: Laptop | G9: 1 | H9: 45000 | I9: 12-01-2025 | J9: =H9*G9 -> 45000 | K9: =VLOOKUP(F9,Product_Master!$A$1:$C$4,3,FALSE*Sales_Data!F5) -> 18 | L9: =J9+K9 -> 45018
C10: 305 | D10: North | E10: Amit | F10: Mobile | G10: 4 | H10: 15000 | I10: 15-01-2025 | J10: =H10*G10 -> 60000 | K10: =VLOOKUP(F10,Product_Master!$A$1:$C$4,3,FALSE*Sales_Data!F6) -> 12 | L10: =J10+K10 -> 60012
C11: 306 | D11: South | E11: Riya | F11: Laptop | G11: 2 | H11: 45000 | I11: 18-01-2025 | J11: =H11*G11 -> 90000 | K11: =VLOOKUP(F11,Product_Master!$A$1:$C$4,3,FALSE*Sales_Data!F7) -> 18 | L11: =J11+K11 -> 90018
I12: GRAND TOTAL | J12: =SUM(J6:J11) -> 414000 | K12: =SUM(K6:K11) -> 90 | L12: =SUM(L6:L11) -> 414090
